Workbook

Sheet 회비입출내역
C1: =참고!$E$5 | F1: =참고!$D$5
A2: 구분 | C2: 전월 | F2: 당월 | I2: 누적
A4: 입금 | D4: =SUM(C5:C7) | G4: =SUM(F5:F7) | J4: =SUM(I5:I7)
A5: 회비 | C5: =SUMIFS(원장!$H:$H,원장!$E:$E,회비입출내역!$A5,원장!$A:$A,회비입출내역!$C$1) | F5: =SUMIFS(원장!$H:$H,원장!$E:$E,회비입출내역!$A5,원장!$A:$A,회비입출내역!$F$1) | I5: =SUMIFS(원장!$H:$H,원장!$E:$E,회비입출내역!$A5)
A6: 지각비 | C6: =SUMIFS(원장!$H:$H,원장!$E:$E,회비입출내역!$A6,원장!$A:$A,회비입출내역!$C$1) | F6: =SUMIFS(원장!$H:$H,원장!$E:$E,회비입출내역!$A6,원장!$A:$A,회비입출내역!$F$1) | I6: =SUMIFS(원장!$H:$H,원장!$E:$E,회비입출내역!$A6)
A7: 이자 | C7: =SUMIFS(원장!$H:$H,원장!$E:$E,회비입출내역!$A7,원장!$A:$A,회비입출내역!$C$1) | F7: =SUMIFS(원장!$H:$H,원장!$E:$E,회비입출내역!$A7,원장!$A:$A,회비입출내역!$F$1) | I7: =SUMIFS(원장!$H:$H,원장!$E:$E,회비입출내역!$A7)
A9: 출금 | D9: =SUM(C10:C15) | G9: =SUM(F10:F15) | J9: =SUM(I10:I15)
A10: 모임비 | C10: =SUMIFS(원장!$H:$H,원장!$E:$E,회비입출내역!$A10,원장!$A:$A,회비입출내역!$C$1) | F10: =SUMIFS(원장!$H:$H,원장!$E:$E,회비입출내역!$A10,원장!$A:$A,회비입출내역!$F$1) | I10: =SUMIFS(원장!$H:$H,원장!$E:$E,회비입출내역!$A10)
A11: 강연비 | C11: =SUMIFS(원장!$H:$H,원장!$E:$E,회비입출내역!$A11,원장!$A:$A,회비입출내역!$C$1) | F11: =SUMIFS(원장!$H:$H,원장!$E:$E,회비입출내역!$A11,원장!$A:$A,회비입출내역!$F$1) | I11: =SUMIFS(원장!$H:$H,원장!$E:$E,회비입출내역!$A11)
A12: 경조사비 | C12: =SUMIFS(원장!$H:$H,원장!$E:$E,회비입출내역!$A12,원장!$A:$A,회비입출내역!$C$1) | F12: =SUMIFS(원장!$H:$H,원장!$E:$E,회비입출내역!$A12,원장!$A:$A,회비입출내역!$F$1) | I12: =SUMIFS(원장!$H:$H,원장!$E:$E,회비입출내역!$A12)
A13: 경품비 | C13: =SUMIFS(원장!$H:$H,원장!$E:$E,회비입출내역!$A13,원장!$A:$A,회비입출내역!$C$1) | F13: =SUMIFS(원장!$H:$H,원장!$E:$E,회비입출내역!$A13,원장!$A:$A,회비입출내역!$F$1) | I13: =SUMIFS(원장!$H:$H,원장!$E:$E,회비입출내역!$A13)
A15: 입금 - 출금 | D15: =SUM(D4:D13) | G15: =SUM(G4:G13) | J15: =SUM(J4:J13)
I16: 7월 1일 잔액 | J16: 7080270
J17: =J16=J15
J18: =J15-J16

Sheet 입금현황
A1: No | B1: 조현민 | C1: 권한해 | D1: 김성환 | E1: 김진호 | F1: 류성준 | G1: 박상용 | H1: 박세환 | I1: 박승현 | J1: 서정권 | K1: 옥지엽 | L1: 최정훈 | M1: 최종하 | N1: 강명신 | O1: 이대로 | P1: 권기표 | Q1: 문인욱 | R1: 박준하 | S1: 황인호 | T1: 김서래 | U1: 백근호 | V1: 윤준원 | W1: 김민기 | X1: 탈퇴멤버 | Y1: 계
E2: 유지 | F2: 유지 | G2: 유지 | H2: 유지 | I2: 유지 | J2: 유지 | K2: 유지 | L2: 유지 | M2: 유지 | N2: 유지 | O2: 유지 | P2: 유지 | Q2: 유지 | R2: 유지 | S2: 유지 | T2: 유지 | U2: 유지 | V2: 유지 | W2: 탈퇴 | X2: 탈퇴
A3: 누적입금액 | B3: =SUM(B4:B101) | C3: =SUM(C4:C101) | D3: =SUM(D4:D101) | E3: =SUM(E4:E101) | F3: =SUM(F4:F101) | G3: =SUM(G4:G101) | H3: =SUM(H4:H101) | I3: =SUM(I4:I101) | ... X3: =SUM(X4:X101) | Y3: =SUM(B3:X3)
A4: 24년 6월 | B4: 100000 | D4: 100000 | E4: 100000 | F4: 100000 | G4: 100000 | H4: 100000 | I4: 100000 | J4: 100000 | K4: 100000 | L4: 100000 | W4: 100000 | Y4: =SUM(B4:X4)
A5: 24년 7월 | B5: 100000 | D5: 100000 | E5: 100000 | F5: 100000 | G5: 100000 | H5: 100000 | I5: 100000 | J5: 100000 | K5: 100000 | L5: 100000 | M5: 100000 | W5: 100000 | X5: 100000 | Y5: =SUM(B5:X5)
A6: 24년 8월 | B6: 100000 | C6: 100000 | D6: 100000 | E6: 100000 | F6: 100000 | G6: 100000 | H6: 100000 | I6: 100000 | J6: 100000 | K6: 100000 | L6: 100000 | M6: 100000 | W6: 100000 | X6: 100000 | Y6: =SUM(B6:X6)
A7: 24년 9월 | B7: 100000 | C7: 100000 | D7: 100000 | E7: 100000 | F7: 100000 | G7: 100000 | H7: 100000 | I7: 100000 | J7: 100000 | K7: 100000 | L7: 100000 | M7: 100000 | W7: 100000 | Y7: =SUM(B7:X7)
A8: 24년 10월 | B8: 100000 | C8: 100000 | D8: 100000 | E8: 100000 | F8: 100000 | G8: 100000 | H8: 100000 | I8: 100000 | J8: 100000 | K8: 100000 | L8: 100000 | M8: 100000 | W8: 100000 | Y8: =SUM(B8:X8)
A9: 24년 11월 | B9: 100000 | C9: 100000 | D9: 100000 | E9: 100000 | F9: 100000 | G9: 100000 | H9: 100000 | I9: 100000 | J9: 100000 | K9: 100000 | L9: 100000 | M9: 100000 | W9: 100000 | Y9: =SUM(B9:X9)
A10: 24년 12월 | B10: 100000 | C10: 100000 | D10: 100000 | E10: 100000 | F10: 100000 | G10: 100000 | H10: 100000 | I10: 100000 | J10: 100000 | K10: 100000 | L10: 100000 | M10: 100000 | N10: 100000 | O10: 100000 | P10: 100000 | W10: 100000 | Y10: =SUM(B10:X10)
A11: 25년 1월 | B11: 100000 | C11: 100000 | D11: 100000 | E11: 100000 | F11: 100000 | G11: 100000 | H11: 100000 | I11: 100000 | J11: 100000 | K11: 100000 | L11: 100000 | M11: 100000 | N11: 100000 | O11: 100000 | P11: 100000 | Q11: 100000 | W11: 100000 | Y11: =SUM(B11:X11)
A12: 25년 2월 | B12: 100000 | C12: 100000 | D12: 100000 | E12: 100000 | F12: 100000 | G12: 100000 | H12: 100000 | I12: 100000 | J12: 100000 | K12: 100000 | L12: 100000 | M12: 100000 | N12: 100000 | O12: 100000 | P12: 100000 | Q12: 100000 | W12: 100000 | Y12: =SUM(B12:X12)
A13: 25년 3월 | B13: 100000 | C13: 100000 | D13: 100000 | E13: 100000 | F13: 100000 | G13: 100000 | H13: 100000 | I13: 100000 | J13: 100000 | K13: 100000 | L13: 100000 | M13: 100000 | N13: 100000 | O13: 100000 | P13: 100000 | Q13: 100000 | W13: 100000 | Y13: =SUM(B13:X13)
A14: 25년 4월 | B14: 100000 | C14: 100000 | D14: 100000 | E14: 100000 | F14: 100000 | G14: 100000 | H14: 100000 | I14: 100000 | J14: 100000 | K14: 100000 | L14: 100000 | M14: 100000 | N14: 100000 | O14: 100000 | P14: 100000 | Q14: 100000 | W14: 100000 | Y14: =SUM(B14:X14)
A15: 25년 5월 | B15: 100000 | C15: 100000 | D15: 100000 | E15: 100000 | F15: 100000 | G15: 100000 | H15: 100000 | I15: 100000 | J15: 100000 | K15: 100000 | L15: 100000 | M15: 100000 | N15: 100000 | O15: 100000 | P15: 100000 | Q15: 100000 | W15: 100000 | Y15: =SUM(B15:X15)
A16: 25년 6월 | B16: 100000 | C16: 100000 | D16: 100000 | E16: 100000 | F16: 100000 | G16: 100000 | H16: 100000 | I16: 100000 | J16: 100000 | K16: 100000 | L16: 100000 | M16: 100000 | N16: 100000 | O16: 100000 | P16: 100000 | Q16: 100000 | W16: 100000 | Y16: =SUM(B16:X16)
A17: 25년 7월 | B17: 100000 | C17: 100000 | D17: 100000 | E17: 100000 | F17: 100000 | G17: 100000 | H17: 100000 | I17: 100000 | J17: 100000 | K17: 100000 | L17: 100000 | M17: 100000 | N17: 100000 | O17: 100000 | P17: 100000 | Q17: 100000 | R17: 100000 | W17: 100000 | Y17: =SUM(B17:X17)
A18: 25년 8월 | B18: 100000 | C18: 100000 | D18: 100000 | E18: 100000 | F18: 100000 | G18: 100000 | H18: 100000 | I18: 100000 | J18: 100000 | K18: 100000 | L18: 100000 | M18: 100000 | N18: 100000 | O18: 100000 | P18: 100000 | Q18: 100000 | R18: 100000 | W18: 100000 | Y18: =SUM(B18:X18)
A19: 25년 9월 | B19: 100000 | C19: 100000 | D19: 100000 | E19: 100000 | F19: 100000 | G19: 100000 | H19: 100000 | I19: 100000 | J19: 100000 | K19: 100000 | L19: 100000 | M19: 100000 | N19: 100000 | O19: 100000 | P19: 100000 | Q19: 100000 | R19: 100000 | W19: 100000 | Y19: =SUM(B19:X19)
A20: 25년 10월 | B20: 100000 | C20: 100000 | D20: 100000 | E20: 100000 | F20: 100000 | G20: 100000 | H20: 100000 | I20: 100000 | J20: 100000 | K20: 100000 | L20: 100000 | M20: 100000 | N20: 100000 | O20: 100000 | P20: 100000 | Q20: 100000 | R20: 100000 | W20: 100000 | Y20: =SUM(B20:X20)
A21: 25년 11월 | B21: 100000 | C21: 100000 | D21: 100000 | E21: 100000 | F21: 100000 | G21: 100000 | H21: 100000 | I21: 100000 | J21: 100000 | K21: 100000 | L21: 100000 | M21: 100000 | N21: 100000 | O21: 100000 | P21: 100000 | Q21: 100000 | R21: 100000 | W21: 100000 | Y21: =SUM(B21:X21)
A22: 25년 12월 | B22: 100000 | C22: 100000 | D22: 100000 | E22: 100000 | F22: 100000 | G22: 100000 | H22: 100000 | I22: 100000 | J22: 100000 | K22: 100000 | L22: 100000 | M22: 100000 | N22: 100000 | O22: 100000 | P22: 100000 | Q22: 100000 | R22: 100000 | S22: 100000 | W22: 100000 | Y22: =SUM(B22:X22)
A23: 26년 1월 | B23: 100000 | C23: 100000 | D23: 100000 | E23: 100000 | F23: 100000 | G23: 100000 | H23: 100000 | I23: 100000 | J23: 100000 | K23: 100000 | L23: 100000 | M23: 100000 | N23: 100000 | O23: 100000 | P23: 100000 | Q23: 100000 | R23: 100000 | S23: 100000 | Y23: =SUM(B23:X23)
A24: 26년 2월 | B24: 100000 | C24: 100000 | D24: 100000 | E24: 100000 | F24: 100000 | G24: 100000 | H24: 100000 | I24: 100000 | J24: 100000 | K24: 100000 | L24: 100000 | M24: 100000 | N24: 100000 | O24: 100000 | P24: 100000 | Q24: 100000 | R24: 100000 | S24: 100000 | T24: 100000 | Y24: =SUM(B24:X24)
A25: 26년 3월 | B25: 100000 | C25: 100000 | D25: 100000 | E25: 100000 | F25: 100000 | G25: 100000 | H25: 100000 | I25: 100000 | J25: 100000 | K25: 100000 | L25: 100000 | M25: 100000 | N25: 100000 | O25: 100000 | P25: 100000 | Q25: 100000 | R25: 100000 | S25: 100000 | T25: 100000 | Y25: =SUM(B25:X25)
A26: 26년 4월 | B26: 100000 | C26: 100000 | D26: 100000 | E26: 100000 | F26: 100000 | G26: 100000 | H26: 100000 | I26: 100000 | J26: 100000 | K26: 100000 | L26: 100000 | M26: 100000 | N26: 100000 | O26: 100000 | P26: 100000 | Q26: 100000 | R26: 100000 | S26: 100000 | T26: 100000 | U26: 100000 | V26: 100000 | Y26: =SUM(B26:X26)
A27: 26년 5월 | B27: 100000 | C27: 100000 | D27: 100000 | E27: 100000 | F27: 100000 | G27: 100000 | H27: 100000 | I27: 100000 | J27: 100000 | K27: 100000 | L27: 100000 | M27: 100000 | N27: 100000 | O27: 100000 | P27: 100000 | Q27: 100000 | R27: 100000 | S27: 100000 | T27: 100000 | U27: 100000 | V27: 100000 | Y27: =SUM(B27:X27)
A28: 26년 6월 | B28: 100000 | C28: 100000 | D28: 100000 | E28: 100000 | F28: 100000 | G28: 100000 | H28: 100000 | I28: 100000 | J28: 100000 | K28: 100000 | L28: 100000 | M28: 100000 | N28: 100000 | O28: 100000 | P28: 100000 | Q28: 100000 | R28: 100000 | S28: 100000 | T28: 100000 | U28: 100000 | V28: 100000 | Y28: =SUM(B28:X28)
A29: 26년 7월 | B29: 100000 | F29: 100000 | G29: 100000 | H29: 100000 | I29: 100000 | J29: 100000 | K29: 100000 | L29: 100000 | M29: 100000 | O29: 100000 | P29: 100000 | Q29: 100000 | R29: 100000 | S29: 100000 | T29: 100000 | V29: 100000 | Y29: =SUM(B29:X29)
A30: 26년 8월 | Y30: =SUM(B30:X30)
A31: 26년 9월 | Y31: =SUM(B31:X31)
A32: 26년 10월 | Y32: =SUM(B32:X32)
A33: 26년 11월 | Y33: =SUM(B33:X33)
A34: 26년 12월 | Y34: =SUM(B34:X34)

Sheet 원장
A1: 연월 | B1: 요일 | C1: 일자 | D1: 분류1 | E1: 분류2 | F1: 차변 | G1: 대변 | H1: 대변-차변 | I1: 비고
A2: 수식 | B2: 수식 | C2: 입력 | D2: 입력 | E2: 입력 | F2: 입력 | G2: 입력 | H2: 수식 | I2: 입력
A3: =RIGHT(YEAR(C3),2)&"년 "&MONTH(C3)&"월" | B3: =VLOOKUP(WEEKDAY(C3,2),참조!$A$1:$B$10,2,) | C3: 45444 | D3: 입금 | E3: 회비 | G3: =SUMIFS(입금현황!$Y:$Y,입금현황!$A:$A,원장!$A3) | H3: =G3-F3 | I3: 월간회비납부
A4: =RIGHT(YEAR(C4),2)&"년 "&MONTH(C4)&"월" | B4: =VLOOKUP(WEEKDAY(C4,2),참조!$A$1:$B$10,2,) | C4: 45472 | D4: 출금 | E4: 모임비 | F4: =417000+260400 | H4: =G4-F4 | I4: 김진호, 모드라운지 언주역점
A5: =RIGHT(YEAR(C5),2)&"년 "&MONTH(C5)&"월" | B5: =VLOOKUP(WEEKDAY(C5,2),참조!$A$1:$B$10,2,) | C5: 45474 | D5: 입금 | E5: 회비 | G5: =SUMIFS(입금현황!$Y:$Y,입금현황!$A:$A,원장!$A5) | H5: =G5-F5 | I5: 월간회비납부
A6: =RIGHT(YEAR(C6),2)&"년 "&MONTH(C6)&"월" | B6: =VLOOKUP(WEEKDAY(C6,2),참조!$A$1:$B$10,2,) | C6: 45500 | D6: 출금 | E6: 모임비 | F6: 547800 | H6: =G6-F6 | I6: 옥지엽, 더브루클린로프트
A7: =RIGHT(YEAR(C7),2)&"년 "&MONTH(C7)&"월" | B7: =VLOOKUP(WEEKDAY(C7,2),참조!$A$1:$B$10,2,) | C7: 45505 | D7: 입금 | E7: 회비 | G7: =SUMIFS(입금현황!$Y:$Y,입금현황!$A:$A,원장!$A7) | H7: =G7-F7 | I7: 월간회비납부
A8: =RIGHT(YEAR(C8),2)&"년 "&MONTH(C8)&"월" | B8: =VLOOKUP(WEEKDAY(C8,2),참조!$A$1:$B$10,2,) | C8: 45535 | D8: 출금 | E8: 모임비 | F8: =311200+100000 | H8: =G8-F8 | I8: 박상용, 골프파티룸 지그로테
A9: =RIGHT(YEAR(C9),2)&"년 "&MONTH(C9)&"월" | B9: =VLOOKUP(WEEKDAY(C9,2),참조!$A$1:$B$10,2,) | C9: 45536 | D9: 입금 | E9: 회비 | G9: =SUMIFS(입금현황!$Y:$Y,입금현황!$A:$A,원장!$A9) | H9: =G9-F9 | I9: 월간회비납부
A10: =RIGHT(YEAR(C10),2)&"년 "&MONTH(C10)&"월" | B10: =VLOOKUP(WEEKDAY(C10,2),참조!$A$1:$B$10,2,) | C10: 45563 | D10: 출금 | E10: 모임비 | F10: =1662200+391600 | H10: =G10-F10 | I10: 그랜드 하얏트 서울 풀사이드 바비큐
A11: =RIGHT(YEAR(C11),2)&"년 "&MONTH(C11)&"월" | B11: =VLOOKUP(WEEKDAY(C11,2),참조!$A$1:$B$10,2,) | C11: 45566 | D11: 입금 | E11: 회비 | G11: =SUMIFS(입금현황!$Y:$Y,입금현황!$A:$A,원장!$A11) | H11: =G11-F11 | I11: 월간회비납부
A12: =RIGHT(YEAR(C12),2)&"년 "&MONTH(C12)&"월" | B12: =VLOOKUP(WEEKDAY(C12,2),참조!$A$1:$B$10,2,) | C12: 45570 | D12: 출금 | E12: 경조사비 | F12: 1000000 | H12: =G12-F12 | I12: 옥지엽, 축의금
A13: =RIGHT(YEAR(C13),2)&"년 "&MONTH(C13)&"월" | B13: =VLOOKUP(WEEKDAY(C13,2),참조!$A$1:$B$10,2,) | C13: 45591 | D13: 출금 | E13: 모임비 | F13: 573000 | H13: =G13-F13 | I13: 박승현, 포레스트 청담
A14: =RIGHT(YEAR(C14),2)&"년 "&MONTH(C14)&"월" | B14: =VLOOKUP(WEEKDAY(C14,2),참조!$A$1:$B$10,2,) | C14: 45597 | D14: 입금 | E14: 회비 | G14: =SUMIFS(입금현황!$Y:$Y,입금현황!$A:$A,원장!$A14) | H14: =G14-F14 | I14: 월간회비납부
A15: =RIGHT(YEAR(C15),2)&"년 "&MONTH(C15)&"월" | B15: =VLOOKUP(WEEKDAY(C15,2),참조!$A$1:$B$10,2,) | C15: 45611 | D15: 출금 | E15: 경조사비 | F15: 92100 | H15: =G15-F15 | I15: 송미숙, 성환이 화환
A16: =RIGHT(YEAR(C16),2)&"년 "&MONTH(C16)&"월" | B16: =VLOOKUP(WEEKDAY(C16,2),참조!$A$1:$B$10,2,) | C16: 45626 | D16: 출금 | E16: 모임비 | F16: =136310+358000+71500 | H16: =G16-F16 | I16: 조현민, 언디파인 논현점
A17: =RIGHT(YEAR(C17),2)&"년 "&MONTH(C17)&"월" | B17: =VLOOKUP(WEEKDAY(C17,2),참조!$A$1:$B$10,2,) | C17: 45627 | D17: 입금 | E17: 회비 | G17: =SUMIFS(입금현황!$Y:$Y,입금현황!$A:$A,원장!$A17) | H17: =G17-F17 | I17: 월간회비납부
A18: =RIGHT(YEAR(C18),2)&"년 "&MONTH(C18)&"월" | B18: =VLOOKUP(WEEKDAY(C18,2),참조!$A$1:$B$10,2,) | C18: 45654 | D18: 출금 | E18: 모임비 | F18: 1627000 | H18: =G18-F18 | I18: 조현민, 언디파인 논현점
A19: =RIGHT(YEAR(C19),2)&"년 "&MONTH(C19)&"월" | B19: =VLOOKUP(WEEKDAY(C19,2),참조!$A$1:$B$10,2,) | C19: 45655 | D19: 출금 | E19: 경조사비 | F19: 1000000 | H19: =G19-F19 | I19: 박상용, 축의금
A20: =RIGHT(YEAR(C20),2)&"년 "&MONTH(C20)&"월" | B20: =VLOOKUP(WEEKDAY(C20,2),참조!$A$1:$B$10,2,) | C20: 45657 | D20: 입금 | E20: 이자 | G20: =46+118+158+264+144+150+258+300 | H20: =G20-F20 | I20: 연간이자_잔액맞추기용
A21: =RIGHT(YEAR(C21),2)&"년 "&MONTH(C21)&"월" | B21: =VLOOKUP(WEEKDAY(C21,2),참조!$A$1:$B$10,2,) | C21: 45658 | D21: 입금 | E21: 회비 | G21: =SUMIFS(입금현황!$Y:$Y,입금현황!$A:$A,원장!$A21) | H21: =G21-F21 | I21: 월간회비납부
A22: =RIGHT(YEAR(C22),2)&"년 "&MONTH(C22)&"월" | B22: =VLOOKUP(WEEKDAY(C22,2),참조!$A$1:$B$10,2,) | C22: 45675 | D22: 출금 | E22: 모임비 | F22: 582400 | H22: =G22-F22 | I22: 조현민, 후라토식당 신사점
A23: =RIGHT(YEAR(C23),2)&"년 "&MONTH(C23)&"월" | B23: =VLOOKUP(WEEKDAY(C23,2),참조!$A$1:$B$10,2,) | C23: 45675 | D23: 출금 | E23: 모임비 | F23: 284900 | H23: =G23-F23 | I23: 박세환, 강남파티룸 아크로셰
A24: =RIGHT(YEAR(C24),2)&"년 "&MONTH(C24)&"월" | B24: =VLOOKUP(WEEKDAY(C24,2),참조!$A$1:$B$10,2,) | C24: 45688 | D24: 출금 | E24: 경조사비 | F24: 400000 | H24: =G24-F24 | I24: 최종하, 생일
A25: =RIGHT(YEAR(C25),2)&"년 "&MONTH(C25)&"월" | B25: =VLOOKUP(WEEKDAY(C25,2),참조!$A$1:$B$10,2,) | C25: 45688 | D25: 입금 | E25: 이자 | G25: 166 | H25: =G25-F25 | I25: 월간이자_잔액맞추기용
A26: =RIGHT(YEAR(C26),2)&"년 "&MONTH(C26)&"월" | B26: =VLOOKUP(WEEKDAY(C26,2),참조!$A$1:$B$10,2,) | C26: 45689 | D26: 입금 | E26: 회비 | G26: =SUMIFS(입금현황!$Y:$Y,입금현황!$A:$A,원장!$A26) | H26: =G26-F26 | I26: 월간회비납부
A27: =RIGHT(YEAR(C27),2)&"년 "&MONTH(C27)&"월" | B27: =VLOOKUP(WEEKDAY(C27,2),참조!$A$1:$B$10,2,) | C27: 45710 | D27: 출금 | E27: 모임비 | F27: 180000 | H27: =G27-F27 | I27: 조현민, 물고기자리논현점
A28: =RIGHT(YEAR(C28),2)&"년 "&MONTH(C28)&"월" | B28: =VLOOKUP(WEEKDAY(C28,2),참조!$A$1:$B$10,2,) | C28: 45710 | D28: 출금 | E28: 모임비 | F28: 110800 | H28: =G28-F28 | I28: 조현민, 도미노피자
A29: =RIGHT(YEAR(C29),2)&"년 "&MONTH(C29)&"월" | B29: =VLOOKUP(WEEKDAY(C29,2),참조!$A$1:$B$10,2,) | C29: 45710 | D29: 출금 | E29: 모임비 | F29: 30000 | H29: =G29-F29 | I29: 조현민,
A30: =RIGHT(YEAR(C30),2)&"년 "&MONTH(C30)&"월" | B30: =VLOOKUP(WEEKDAY(C30,2),참조!$A$1:$B$10,2,) | C30: 45716 | D30: 출금 | E30: 경조사비 | F30: 100000 | H30: =G30-F30 | I30: 박상용, 생일
A31: =RIGHT(YEAR(C31),2)&"년 "&MONTH(C31)&"월" | B31: =VLOOKUP(WEEKDAY(C31,2),참조!$A$1:$B$10,2,) | C31: 45716 | D31: 입금 | E31: 이자 | G31: 266 | H31: =G31-F31 | I31: 월간이자_잔액맞추기용
A32: =RIGHT(YEAR(C32),2)&"년 "&MONTH(C32)&"월" | B32: =VLOOKUP(WEEKDAY(C32,2),참조!$A$1:$B$10,2,) | C32: 45717 | D32: 입금 | E32: 회비 | G32: =SUMIFS(입금현황!$Y:$Y,입금현황!$A:$A,원장!$A32) | H32: =G32-F32 | I32: 월간회비납부
A33: =RIGHT(YEAR(C33),2)&"년 "&MONTH(C33)&"월" | B33: =VLOOKUP(WEEKDAY(C33,2),참조!$A$1:$B$10,2,) | C33: 45726 | D33: 출금 | E33: 모임비 | F33: 90000 | G33: =-6500*3 | H33: =G33-F33 | I33: 골프공 맞추기
A34: =RIGHT(YEAR(C34),2)&"년 "&MONTH(C34)&"월" | B34: =VLOOKUP(WEEKDAY(C34,2),참조!$A$1:$B$10,2,) | C34: 45745 | D34: 출금 | E34: 모임비 | F34: 480000 | H34: =G34-F34 | I34: 최정훈, 장소예약
A35: =RIGHT(YEAR(C35),2)&"년 "&MONTH(C35)&"월" | B35: =VLOOKUP(WEEKDAY(C35,2),참조!$A$1:$B$10,2,) | C35: 45745 | D35: 출금 | E35: 모임비 | F35: 497270 | H35: =G35-F35 | I35: 조현민, 장보기
A36: =RIGHT(YEAR(C36),2)&"년 "&MONTH(C36)&"월" | B36: =VLOOKUP(WEEKDAY(C36,2),참조!$A$1:$B$10,2,) | C36: 45745 | D36: 입금 | E36: 이자 | G36: 253 | H36: =G36-F36 | I36: 월간이자_잔액맞추기용
A37: =RIGHT(YEAR(C37),2)&"년 "&MONTH(C37)&"월" | B37: =VLOOKUP(WEEKDAY(C37,2),참조!$A$1:$B$10,2,) | C37: 45748 | D37: 입금 | E37: 회비 | G37: =SUMIFS(입금현황!$Y:$Y,입금현황!$A:$A,원장!$A37) | H37: =G37-F37 | I37: 월간회비납부
A38: =RIGHT(YEAR(C38),2)&"년 "&MONTH(C38)&"월" | B38: =VLOOKUP(WEEKDAY(C38,2),참조!$A$1:$B$10,2,) | C38: 45773 | D38: 출금 | E38: 모임비 | F38: 1276000 | H38: =G38-F38 | I38: 최종하, 몽중헌 청담
A39: =RIGHT(YEAR(C39),2)&"년 "&MONTH(C39)&"월" | B39: =VLOOKUP(WEEKDAY(C39,2),참조!$A$1:$B$10,2,) | C39: 45778 | D39: 입금 | E39: 회비 | G39: =SUMIFS(입금현황!$Y:$Y,입금현황!$A:$A,원장!$A39) | H39: =G39-F39 | I39: 월간회비납부
A40: =RIGHT(YEAR(C40),2)&"년 "&MONTH(C40)&"월" | B40: =VLOOKUP(WEEKDAY(C40,2),참조!$A$1:$B$10,2,) | C40: 45808 | D40: 출금 | E40: 경조사비 | F40: =INT(607500/3) | H40: =G40-F40 | I40: 김민기, 업무축하
...

Sheet 증감분석
B2: 연월 | C2: 개월수 역산 | D2: 입금 | H2: 출금
B3: 연월 | C3: 개월수 역산 | D3: 회비 | E3: 지각비 | F3: 이자 | G3: 계 | H3: 모임비 | I3: 강연비 | J3: 경조사비 | K3: 경품비 | L3: 계
B4: 전체평균 | D4: =AVERAGEIFS(D10:D2203,D10:D2203,">0") | E4: =AVERAGEIFS(E10:E2203,E10:E2203,">0") | F4: =AVERAGEIFS(F10:F2203,F10:F2203,">0") | G4: =AVERAGEIFS(G10:G2203,G10:G2203,">0") | H4: =AVERAGEIFS(H10:H2203,H10:H2203,"<0") | I4: =AVERAGEIFS(I10:I2203,I10:I2203,"<0") | J4: =AVERAGEIFS(J10:J2203,J10:J2203,"<0") | K4: =AVERAGEIFS(K10:K2203,K10:K2203,"<0") | L4: =AVERAGEIFS(L10:L2203,L10:L2203,"<0")
A5: 3 | B5: 최근3개월평균 | D5: =AVERAGEIFS(D8:D2201,$C$10:$C$2203,"<=3") | E5: =AVERAGEIFS(E8:E2201,$C$10:$C$2203,"<=3") | F5: =AVERAGEIFS(F8:F2201,$C$10:$C$2203,"<=3") | G5: =AVERAGEIFS(G8:G2201,$C$10:$C$2203,"<=3") | H5: =AVERAGEIFS(H$10:H$2203,$C$10:$C$2203,"<=3") | I5: =AVERAGEIFS(I$10:I$2203,$C$10:$C$2203,"<=3") | J5: =AVERAGEIFS(J$10:J$2203,$C$10:$C$2203,"<=3") | K5: =AVERAGEIFS(K$10:K$2203,$C$10:$C$2203,"<=3") | L5: =AVERAGEIFS(L$10:L$2203,$C$10:$C$2203,"<=3")
A6: 6 | B6: 최근6개월평균 | D6: =AVERAGEIFS(D9:D2202,$C$10:$C$2203,"<=6") | E6: =AVERAGEIFS(E9:E2202,$C$10:$C$2203,"<=6") | F6: =AVERAGEIFS(F9:F2202,$C$10:$C$2203,"<=6") | G6: =AVERAGEIFS(G9:G2202,$C$10:$C$2203,"<=6") | H6: =AVERAGEIFS(H$10:H$2203,$C$10:$C$2203,"<=6") | I6: =AVERAGEIFS(I$10:I$2203,$C$10:$C$2203,"<=6") | J6: =AVERAGEIFS(J$10:J$2203,$C$10:$C$2203,"<=6") | K6: =AVERAGEIFS(K$10:K$2203,$C$10:$C$2203,"<=6") | L6: =AVERAGEIFS(L$10:L$2203,$C$10:$C$2203,"<=6")
A7: 12 | B7: 최근12개월평균 | D7: =AVERAGEIFS(D10:D2203,$C$10:$C$2203,"<=12") | E7: =AVERAGEIFS(E10:E2203,$C$10:$C$2203,"<=12") | F7: =AVERAGEIFS(F10:F2203,$C$10:$C$2203,"<=12") | G7: =AVERAGEIFS(G10:G2203,$C$10:$C$2203,"<=12") | H7: =AVERAGEIFS(H$10:H$2203,$C$10:$C$2203,"<=12") | I7: =AVERAGEIFS(I$10:I$2203,$C$10:$C$2203,"<=12") | J7: =AVERAGEIFS(J$10:J$2203,$C$10:$C$2203,"<=12") | K7: =AVERAGEIFS(K$10:K$2203,$C$10:$C$2203,"<=12") | L7: =AVERAGEIFS(L$10:L$2203,$C$10:$C$2203,"<=12")
B9: 연월 | C9: 개월수 역산 | D9: 입금 | E9: 입금 | F9: 입금 | G9: 입금 | H9: 출금 | I9: 출금 | J9: 출금 | K9: 출금 | L9: 출금 | M9: 입금-출금 | P9: 차트용
B10: 연월 | C10: 개월수 역산 | D10: 회비 | E10: 지각비 | F10: 이자 | G10: 계 | H10: 모임비 | I10: 강연비 | J10: 경조사비 | K10: 경품비 | L10: 계 | M10: 계 | N10: 누적 | P10: 연월 | Q10: 입금 | R10: 출금 | S10: 누적
B11: 24년 6월 | C11: =IF($B11=참고!$D$5,1,C12+1) | D11: =SUMIFS(원장!$H:$H,원장!$A:$A,증감분석!$B11,원장!$D:$D,증감분석!D$9,원장!$E:$E,증감분석!D$10) | E11: =SUMIFS(원장!$H:$H,원장!$A:$A,증감분석!$B11,원장!$D:$D,증감분석!E$9,원장!$E:$E,증감분석!E$10) | F11: =SUMIFS(원장!$H:$H,원장!$A:$A,증감분석!$B11,원장!$D:$D,증감분석!F$9,원장!$E:$E,증감분석!F$10) | G11: =SUM(D11:F11) | H11: =SUMIFS(원장!$H:$H,원장!$A:$A,증감분석!$B11,원장!$D:$D,증감분석!H$9,원장!$E:$E,증감분석!H$10) | I11: =SUMIFS(원장!$H:$H,원장!$A:$A,증감분석!$B11,원장!$D:$D,증감분석!I$9,원장!$E:$E,증감분석!I$10) | J11: =SUMIFS(원장!$H:$H,원장!$A:$A,증감분석!$B11,원장!$D:$D,증감분석!J$9,원장!$E:$E,증감분석!J$10) | K11: =SUMIFS(원장!$H:$H,원장!$A:$A,증감분석!$B11,원장!$D:$D,증감분석!K$9,원장!$E:$E,증감분석!K$10) | L11: =SUM(H11:K11) | M11: =G11+L11 | N11: =SUM($M$11:M11) | P11: =B11 | Q11: =G11 | R11: =-L11 | S11: =N11
B12: 24년 7월 | C12: =IF($B12=참고!$D$5,1,C13+1) | D12: =SUMIFS(원장!$H:$H,원장!$A:$A,증감분석!$B12,원장!$D:$D,증감분석!D$9,원장!$E:$E,증감분석!D$10) | E12: =SUMIFS(원장!$H:$H,원장!$A:$A,증감분석!$B12,원장!$D:$D,증감분석!E$9,원장!$E:$E,증감분석!E$10) | F12: =SUMIFS(원장!$H:$H,원장!$A:$A,증감분석!$B12,원장!$D:$D,증감분석!F$9,원장!$E:$E,증감분석!F$10) | G12: =SUM(D12:F12) | H12: =SUMIFS(원장!$H:$H,원장!$A:$A,증감분석!$B12,원장!$D:$D,증감분석!H$9,원장!$E:$E,증감분석!H$10) | I12: =SUMIFS(원장!$H:$H,원장!$A:$A,증감분석!$B12,원장!$D:$D,증감분석!I$9,원장!$E:$E,증감분석!I$10) | J12: =SUMIFS(원장!$H:$H,원장!$A:$A,증감분석!$B12,원장!$D:$D,증감분석!J$9,원장!$E:$E,증감분석!J$10) | K12: =SUMIFS(원장!$H:$H,원장!$A:$A,증감분석!$B12,원장!$D:$D,증감분석!K$9,원장!$E:$E,증감분석!K$10) | L12: =SUM(H12:K12) | M12: =G12+L12 | N12: =SUM($M$11:M12) | P12: =B12 | Q12: =G12 | R12: =-L12 | S12: =N12
B13: 24년 8월 | C13: =IF($B13=참고!$D$5,1,C14+1) | D13: =SUMIFS(원장!$H:$H,원장!$A:$A,증감분석!$B13,원장!$D:$D,증감분석!D$9,원장!$E:$E,증감분석!D$10) | E13: =SUMIFS(원장!$H:$H,원장!$A:$A,증감분석!$B13,원장!$D:$D,증감분석!E$9,원장!$E:$E,증감분석!E$10) | F13: =SUMIFS(원장!$H:$H,원장!$A:$A,증감분석!$B13,원장!$D:$D,증감분석!F$9,원장!$E:$E,증감분석!F$10) | G13: =SUM(D13:F13) | H13: =SUMIFS(원장!$H:$H,원장!$A:$A,증감분석!$B13,원장!$D:$D,증감분석!H$9,원장!$E:$E,증감분석!H$10) | I13: =SUMIFS(원장!$H:$H,원장!$A:$A,증감분석!$B13,원장!$D:$D,증감분석!I$9,원장!$E:$E,증감분석!I$10) | J13: =SUMIFS(원장!$H:$H,원장!$A:$A,증감분석!$B13,원장!$D:$D,증감분석!J$9,원장!$E:$E,증감분석!J$10) | K13: =SUMIFS(원장!$H:$H,원장!$A:$A,증감분석!$B13,원장!$D:$D,증감분석!K$9,원장!$E:$E,증감분석!K$10) | L13: =SUM(H13:K13) | M13: =G13+L13 | N13: =SUM($M$11:M13) | P13: =B13 | Q13: =G13 | R13: =-L13 | S13: =N13
B14: 24년 9월 | C14: =IF($B14=참고!$D$5,1,C15+1) | D14: =SUMIFS(원장!$H:$H,원장!$A:$A,증감분석!$B14,원장!$D:$D,증감분석!D$9,원장!$E:$E,증감분석!D$10) | E14: =SUMIFS(원장!$H:$H,원장!$A:$A,증감분석!$B14,원장!$D:$D,증감분석!E$9,원장!$E:$E,증감분석!E$10) | F14: =SUMIFS(원장!$H:$H,원장!$A:$A,증감분석!$B14,원장!$D:$D,증감분석!F$9,원장!$E:$E,증감분석!F$10) | G14: =SUM(D14:F14) | H14: =SUMIFS(원장!$H:$H,원장!$A:$A,증감분석!$B14,원장!$D:$D,증감분석!H$9,원장!$E:$E,증감분석!H$10) | I14: =SUMIFS(원장!$H:$H,원장!$A:$A,증감분석!$B14,원장!$D:$D,증감분석!I$9,원장!$E:$E,증감분석!I$10) | J14: =SUMIFS(원장!$H:$H,원장!$A:$A,증감분석!$B14,원장!$D:$D,증감분석!J$9,원장!$E:$E,증감분석!J$10) | K14: =SUMIFS(원장!$H:$H,원장!$A:$A,증감분석!$B14,원장!$D:$D,증감분석!K$9,원장!$E:$E,증감분석!K$10) | L14: =SUM(H14:K14) | M14: =G14+L14 | N14: =SUM($M$11:M14) | P14: =B14 | Q14: =G14 | R14: =-L14 | S14: =N14
B15: 24년 10월 | C15: =IF($B15=참고!$D$5,1,C16+1) | D15: =SUMIFS(원장!$H:$H,원장!$A:$A,증감분석!$B15,원장!$D:$D,증감분석!D$9,원장!$E:$E,증감분석!D$10) | E15: =SUMIFS(원장!$H:$H,원장!$A:$A,증감분석!$B15,원장!$D:$D,증감분석!E$9,원장!$E:$E,증감분석!E$10) | F15: =SUMIFS(원장!$H:$H,원장!$A:$A,증감분석!$B15,원장!$D:$D,증감분석!F$9,원장!$E:$E,증감분석!F$10) | G15: =SUM(D15:F15) | H15: =SUMIFS(원장!$H:$H,원장!$A:$A,증감분석!$B15,원장!$D:$D,증감분석!H$9,원장!$E:$E,증감분석!H$10) | I15: =SUMIFS(원장!$H:$H,원장!$A:$A,증감분석!$B15,원장!$D:$D,증감분석!I$9,원장!$E:$E,증감분석!I$10) | J15: =SUMIFS(원장!$H:$H,원장!$A:$A,증감분석!$B15,원장!$D:$D,증감분석!J$9,원장!$E:$E,증감분석!J$10) | K15: =SUMIFS(원장!$H:$H,원장!$A:$A,증감분석!$B15,원장!$D:$D,증감분석!K$9,원장!$E:$E,증감분석!K$10) | L15: =SUM(H15:K15) | M15: =G15+L15 | N15: =SUM($M$11:M15) | P15: =B15 | Q15: =G15 | R15: =-L15 | S15: =N15
B16: 24년 11월 | C16: =IF($B16=참고!$D$5,1,C17+1) | D16: =SUMIFS(원장!$H:$H,원장!$A:$A,증감분석!$B16,원장!$D:$D,증감분석!D$9,원장!$E:$E,증감분석!D$10) | E16: =SUMIFS(원장!$H:$H,원장!$A:$A,증감분석!$B16,원장!$D:$D,증감분석!E$9,원장!$E:$E,증감분석!E$10) | F16: =SUMIFS(원장!$H:$H,원장!$A:$A,증감분석!$B16,원장!$D:$D,증감분석!F$9,원장!$E:$E,증감분석!F$10) | G16: =SUM(D16:F16) | H16: =SUMIFS(원장!$H:$H,원장!$A:$A,증감분석!$B16,원장!$D:$D,증감분석!H$9,원장!$E:$E,증감분석!H$10) | I16: =SUMIFS(원장!$H:$H,원장!$A:$A,증감분석!$B16,원장!$D:$D,증감분석!I$9,원장!$E:$E,증감분석!I$10) | J16: =SUMIFS(원장!$H:$H,원장!$A:$A,증감분석!$B16,원장!$D:$D,증감분석!J$9,원장!$E:$E,증감분석!J$10) | K16: =SUMIFS(원장!$H:$H,원장!$A:$A,증감분석!$B16,원장!$D:$D,증감분석!K$9,원장!$E:$E,증감분석!K$10) | L16: =SUM(H16:K16) | M16: =G16+L16 | N16: =SUM($M$11:M16) | P16: =B16 | Q16: =G16 | R16: =-L16 | S16: =N16
B17: 24년 12월 | C17: =IF($B17=참고!$D$5,1,C18+1) | D17: =SUMIFS(원장!$H:$H,원장!$A:$A,증감분석!$B17,원장!$D:$D,증감분석!D$9,원장!$E:$E,증감분석!D$10) | E17: =SUMIFS(원장!$H:$H,원장!$A:$A,증감분석!$B17,원장!$D:$D,증감분석!E$9,원장!$E:$E,증감분석!E$10) | F17: =SUMIFS(원장!$H:$H,원장!$A:$A,증감분석!$B17,원장!$D:$D,증감분석!F$9,원장!$E:$E,증감분석!F$10) | G17: =SUM(D17:F17) | H17: =SUMIFS(원장!$H:$H,원장!$A:$A,증감분석!$B17,원장!$D:$D,증감분석!H$9,원장!$E:$E,증감분석!H$10) | I17: =SUMIFS(원장!$H:$H,원장!$A:$A,증감분석!$B17,원장!$D:$D,증감분석!I$9,원장!$E:$E,증감분석!I$10) | J17: =SUMIFS(원장!$H:$H,원장!$A:$A,증감분석!$B17,원장!$D:$D,증감분석!J$9,원장!$E:$E,증감분석!J$10) | K17: =SUMIFS(원장!$H:$H,원장!$A:$A,증감분석!$B17,원장!$D:$D,증감분석!K$9,원장!$E:$E,증감분석!K$10) | L17: =SUM(H17:K17) | M17: =G17+L17 | N17: =SUM($M$11:M17) | P17: =B17 | Q17: =G17 | R17: =-L17 | S17: =N17
B18: 25년 1월 | C18: =IF($B18=참고!$D$5,1,C19+1) | D18: =SUMIFS(원장!$H:$H,원장!$A:$A,증감분석!$B18,원장!$D:$D,증감분석!D$9,원장!$E:$E,증감분석!D$10) | E18: =SUMIFS(원장!$H:$H,원장!$A:$A,증감분석!$B18,원장!$D:$D,증감분석!E$9,원장!$E:$E,증감분석!E$10) | F18: =SUMIFS(원장!$H:$H,원장!$A:$A,증감분석!$B18,원장!$D:$D,증감분석!F$9,원장!$E:$E,증감분석!F$10) | G18: =SUM(D18:F18) | H18: =SUMIFS(원장!$H:$H,원장!$A:$A,증감분석!$B18,원장!$D:$D,증감분석!H$9,원장!$E:$E,증감분석!H$10) | I18: =SUMIFS(원장!$H:$H,원장!$A:$A,증감분석!$B18,원장!$D:$D,증감분석!I$9,원장!$E:$E,증감분석!I$10) | J18: =SUMIFS(원장!$H:$H,원장!$A:$A,증감분석!$B18,원장!$D:$D,증감분석!J$9,원장!$E:$E,증감분석!J$10) | K18: =SUMIFS(원장!$H:$H,원장!$A:$A,증감분석!$B18,원장!$D:$D,증감분석!K$9,원장!$E:$E,증감분석!K$10) | L18: =SUM(H18:K18) | M18: =G18+L18 | N18: =SUM($M$11:M18) | P18: =B18 | Q18: =G18 | R18: =-L18 | S18: =N18
B19: 25년 2월 | C19: =IF($B19=참고!$D$5,1,C20+1) | D19: =SUMIFS(원장!$H:$H,원장!$A:$A,증감분석!$B19,원장!$D:$D,증감분석!D$9,원장!$E:$E,증감분석!D$10) | E19: =SUMIFS(원장!$H:$H,원장!$A:$A,증감분석!$B19,원장!$D:$D,증감분석!E$9,원장!$E:$E,증감분석!E$10) | F19: =SUMIFS(원장!$H:$H,원장!$A:$A,증감분석!$B19,원장!$D:$D,증감분석!F$9,원장!$E:$E,증감분석!F$10) | G19: =SUM(D19:F19) | H19: =SUMIFS(원장!$H:$H,원장!$A:$A,증감분석!$B19,원장!$D:$D,증감분석!H$9,원장!$E:$E,증감분석!H$10) | I19: =SUMIFS(원장!$H:$H,원장!$A:$A,증감분석!$B19,원장!$D:$D,증감분석!I$9,원장!$E:$E,증감분석!I$10) | J19: =SUMIFS(원장!$H:$H,원장!$A:$A,증감분석!$B19,원장!$D:$D,증감분석!J$9,원장!$E:$E,증감분석!J$10) | K19: =SUMIFS(원장!$H:$H,원장!$A:$A,증감분석!$B19,원장!$D:$D,증감분석!K$9,원장!$E:$E,증감분석!K$10) | L19: =SUM(H19:K19) | M19: =G19+L19 | N19: =SUM($M$11:M19) | P19: =B19 | Q19: =G19 | R19: =-L19 | S19: =N19
B20: 25년 3월 | C20: =IF($B20=참고!$D$5,1,C21+1) | D20: =SUMIFS(원장!$H:$H,원장!$A:$A,증감분석!$B20,원장!$D:$D,증감분석!D$9,원장!$E:$E,증감분석!D$10) | E20: =SUMIFS(원장!$H:$H,원장!$A:$A,증감분석!$B20,원장!$D:$D,증감분석!E$9,원장!$E:$E,증감분석!E$10) | F20: =SUMIFS(원장!$H:$H,원장!$A:$A,증감분석!$B20,원장!$D:$D,증감분석!F$9,원장!$E:$E,증감분석!F$10) | G20: =SUM(D20:F20) | H20: =SUMIFS(원장!$H:$H,원장!$A:$A,증감분석!$B20,원장!$D:$D,증감분석!H$9,원장!$E:$E,증감분석!H$10) | I20: =SUMIFS(원장!$H:$H,원장!$A:$A,증감분석!$B20,원장!$D:$D,증감분석!I$9,원장!$E:$E,증감분석!I$10) | J20: =SUMIFS(원장!$H:$H,원장!$A:$A,증감분석!$B20,원장!$D:$D,증감분석!J$9,원장!$E:$E,증감분석!J$10) | K20: =SUMIFS(원장!$H:$H,원장!$A:$A,증감분석!$B20,원장!$D:$D,증감분석!K$9,원장!$E:$E,증감분석!K$10) | L20: =SUM(H20:K20) | M20: =G20+L20 | N20: =SUM($M$11:M20) | P20: =B20 | Q20: =G20 | R20: =-L20 | S20: =N20
B21: 25년 4월 | C21: =IF($B21=참고!$D$5,1,C22+1) | D21: =SUMIFS(원장!$H:$H,원장!$A:$A,증감분석!$B21,원장!$D:$D,증감분석!D$9,원장!$E:$E,증감분석!D$10) | E21: =SUMIFS(원장!$H:$H,원장!$A:$A,증감분석!$B21,원장!$D:$D,증감분석!E$9,원장!$E:$E,증감분석!E$10) | F21: =SUMIFS(원장!$H:$H,원장!$A:$A,증감분석!$B21,원장!$D:$D,증감분석!F$9,원장!$E:$E,증감분석!F$10) | G21: =SUM(D21:F21) | H21: =SUMIFS(원장!$H:$H,원장!$A:$A,증감분석!$B21,원장!$D:$D,증감분석!H$9,원장!$E:$E,증감분석!H$10) | I21: =SUMIFS(원장!$H:$H,원장!$A:$A,증감분석!$B21,원장!$D:$D,증감분석!I$9,원장!$E:$E,증감분석!I$10) | J21: =SUMIFS(원장!$H:$H,원장!$A:$A,증감분석!$B21,원장!$D:$D,증감분석!J$9,원장!$E:$E,증감분석!J$10) | K21: =SUMIFS(원장!$H:$H,원장!$A:$A,증감분석!$B21,원장!$D:$D,증감분석!K$9,원장!$E:$E,증감분석!K$10) | L21: =SUM(H21:K21) | M21: =G21+L21 | N21: =SUM($M$11:M21) | P21: =B21 | Q21: =G21 | R21: =-L21 | S21: =N21
B22: 25년 5월 | C22: =IF($B22=참고!$D$5,1,C23+1) | D22: =SUMIFS(원장!$H:$H,원장!$A:$A,증감분석!$B22,원장!$D:$D,증감분석!D$9,원장!$E:$E,증감분석!D$10) | E22: =SUMIFS(원장!$H:$H,원장!$A:$A,증감분석!$B22,원장!$D:$D,증감분석!E$9,원장!$E:$E,증감분석!E$10) | F22: =SUMIFS(원장!$H:$H,원장!$A:$A,증감분석!$B22,원장!$D:$D,증감분석!F$9,원장!$E:$E,증감분석!F$10) | G22: =SUM(D22:F22) | H22: =SUMIFS(원장!$H:$H,원장!$A:$A,증감분석!$B22,원장!$D:$D,증감분석!H$9,원장!$E:$E,증감분석!H$10) | I22: =SUMIFS(원장!$H:$H,원장!$A:$A,증감분석!$B22,원장!$D:$D,증감분석!I$9,원장!$E:$E,증감분석!I$10) | J22: =SUMIFS(원장!$H:$H,원장!$A:$A,증감분석!$B22,원장!$D:$D,증감분석!J$9,원장!$E:$E,증감분석!J$10) | K22: =SUMIFS(원장!$H:$H,원장!$A:$A,증감분석!$B22,원장!$D:$D,증감분석!K$9,원장!$E:$E,증감분석!K$10) | L22: =SUM(H22:K22) | M22: =G22+L22 | N22: =SUM($M$11:M22) | P22: =B22 | Q22: =G22 | R22: =-L22 | S22: =N22
... B36: 26년 7월 | C36: =IF($B36=참고!$D$5,1,C37+1) | D36: =SUMIFS(원장!$H:$H,원장!$A:$A,증감분석!$B36,원장!$D:$D,증감분석!D$9,원장!$E:$E,증감분석!D$10) | E36: =SUMIFS(원장!$H:$H,원장!$A:$A,증감분석!$B36,원장!$D:$D,증감분석!E$9,원장!$E:$E,증감분석!E$10) | F36: =SUMIFS(원장!$H:$H,원장!$A:$A,증감분석!$B36,원장!$D:$D,증감분석!F$9,원장!$E:$E,증감분석!F$10) | G36: =SUM(D36:F36) | H36: =SUMIFS(원장!$H:$H,원장!$A:$A,증감분석!$B36,원장!$D:$D,증감분석!H$9,원장!$E:$E,증감분석!H$10) | I36: =SUMIFS(원장!$H:$H,원장!$A:$A,증감분석!$B36,원장!$D:$D,증감분석!I$9,원장!$E:$E,증감분석!I$10) | J36: =SUMIFS(원장!$H:$H,원장!$A:$A,증감분석!$B36,원장!$D:$D,증감분석!J$9,원장!$E:$E,증감분석!J$10) | K36: =SUMIFS(원장!$H:$H,원장!$A:$A,증감분석!$B36,원장!$D:$D,증감분석!K$9,원장!$E:$E,증감분석!K$10) | L36: =SUM(H36:K36) | M36: =G36+L36 | N36: =SUM($M$11:M36) | P36: =B36 | Q36: =G36 | R36: =-L36 | S36: =N36

Sheet 증감분석차트

Sheet 참고
A1: =TODAY() | B1: =YEAR(A1) | C1: =MONTH(A1) | D1: =IF(C1-1=0,12,C1-1) | E1: =IF(D1-1=0,12,D1-1) | F1: =IF(E1-1=0,12,E1-1) | G1: =IF(F1-1=0,12,F1-1) | H1: =IF(G1-1=0,12,G1-1) | I1: =IF(H1-1=0,12,H1-1) | J1: =IF(I1-1=0,12,I1-1) | K1: =IF(J1-1=0,12,J1-1) | ... O1: =IF(N1-1=0,12,N1-1)
B2: =RIGHT(B1,2) | C2: =B2-1
B3: =B2&"년" | C3: =C2&"년"
D4: =D1&"월" | E4: =E1&"월" | F4: =F1&"월" | G4: =G1&"월" | H4: =H1&"월" | I4: =I1&"월" | J4: =J1&"월" | K4: =K1&"월" | ... O4: =O1&"월"
D5: =IF(D1>=$C$1,$C$3&" "&D4,$B$3&" "&D4) | E5: =IF(E1>=$C$1,$C$3&" "&E4,$B$3&" "&E4) | F5: =IF(F1>=$C$1,$C$3&" "&F4,$B$3&" "&F4) | G5: =IF(G1>=$C$1,$C$3&" "&G4,$B$3&" "&G4) | H5: =IF(H1>=$C$1,$C$3&" "&H4,$B$3&" "&H4) | I5: =IF(I1>=$C$1,$C$3&" "&I4,$B$3&" "&I4) | J5: =IF(J1>=$C$1,$C$3&" "&J4,$B$3&" "&J4) | K5: =IF(K1>=$C$1,$C$3&" "&K4,$B$3&" "&K4) | ... O5: =IF(O1>=$C$1,$C$3&" "&O4,$B$3&" "&O4)

Sheet 주요정보
E9: 주요 정보 | F9: =회비입출내역!F1 | G9: =회비입출내역!$C$1 | H9: =증감분석!B5 | I9: =증감분석!B6 | J9: =증감분석!$B$7 | K9: 누적
E10: 입금액 | F10: =회비입출내역!$G$4 | G10: =회비입출내역!$D$4 | H10: =증감분석!$G$5 | I10: =증감분석!$G$6 | J10: =증감분석!$G$7 | K10: =회비입출내역!$J$4
E11: 출금액 | F11: =회비입출내역!$G$9 | G11: =회비입출내역!$D$9 | H11: =증감분석!$L$5 | I11: =증감분석!$L$6 | J11: =증감분석!$L$7 | K11: =회비입출내역!$J$9
E12: 입금액 - 출금액 | F12: =SUM(F10:F11) | G12: =SUM(G10:G11) | H12: =SUM(H10:H11) | I12: =SUM(I10:I11) | J12: =SUM(J10:J11) | K12: =SUM(K10:K11)

Sheet 참조
A1: 월별Tab Weekday 함수용
A2: 숫자 | B2: 요일
A3: 1 | B3: 월
A4: 2 | B4: 화
A5: 3 | B5: 수
A6: 4 | B6: 목
A7: 5 | B7: 금
A8: 6 | B8: 토
A9: 7 | B9: 일
